<?xml version="1.0" ?>
<!-- =================================================================================== -->
<!-- |    This document was autogenerated by xacro from robot_arm.urdf.xacro           | -->
<!-- |    EDITING THIS FILE BY HAND IS NOT RECOMMENDED                                 | -->
<!-- =================================================================================== -->
<robot name="medical_grade_neurosurgical_robot">
  <!-- Medical-grade materials -->
  <material name="medical_base">
    <color rgba="0.3 0.3 0.35 1.0"/>
  </material>
  <material name="medical_grey">
    <color rgba="0.85 0.85 0.88 1.0"/>
  </material>
  <material name="motor_black">
    <color rgba="0.15 0.15 0.15 1.0"/>
  </material>
  <material name="surgical_steel">
    <color rgba="0.9 0.9 0.95 1.0"/>
  </material>
  <material name="safety_orange">
    <color rgba="1.0 0.4 0.0 1.0"/>
  </material>
  <material name="cable_black">
    <color rgba="0.1 0.1 0.1 1.0"/>
  </material>
  <!-- Needle material (highly visible for safety) -->
  <material name="needle_gold">
    <color rgba="1.0 0.8 0.0 1.0"/>
  </material>
  <!-- Wall mount material -->
  <material name="wall_mount_steel">
    <color rgba="0.7 0.7 0.75 1.0"/>
  </material>
  <!-- Wall plate material -->
  <material name="wall_surface">
    <color rgba="0.9 0.9 0.92 1.0"/>
  </material>
  <material name="mounting_holes">
    <color rgba="0.3 0.3 0.3 1.0"/>
  </material>
  <!-- World Link (FIXED - Wall bottom now sits at grid level) -->
  <link name="world">
    <!-- Main wall plate surface - MOVED UP so bottom sits at Z=0 -->
    <visual>
      <origin rpy="0 0 0" xyz="0 0 0.3"/>
      <geometry>
        <box size="0.8 0.05 0.6"/>
      </geometry>
      <material name="wall_surface"/>
    </visual>
    <!-- Mounting holes (decorative) - ADJUSTED for new wall position -->
    <visual>
      <origin rpy="1.570795 0 0" xyz="0.2 -0.027000000000000003 0.44999999999999996"/>
      <geometry>
        <cylinder length="0.008" radius="0.005"/>
      </geometry>
      <material name="mounting_holes"/>
    </visual>
    <visual>
      <origin rpy="1.570795 0 0" xyz="-0.2 -0.027000000000000003 0.44999999999999996"/>
      <geometry>
        <cylinder length="0.008" radius="0.005"/>
      </geometry>
      <material name="mounting_holes"/>
    </visual>
    <visual>
      <origin rpy="1.570795 0 0" xyz="0.2 -0.027000000000000003 0.15"/>
      <geometry>
        <cylinder length="0.008" radius="0.005"/>
      </geometry>
      <material name="mounting_holes"/>
    </visual>
    <visual>
      <origin rpy="1.570795 0 0" xyz="-0.2 -0.027000000000000003 0.15"/>
      <geometry>
        <cylinder length="0.008" radius="0.005"/>
      </geometry>
      <material name="mounting_holes"/>
    </visual>
    <!-- Collision - MOVED UP to match visual -->
    <collision>
      <origin rpy="0 0 0" xyz="0 0 0.3"/>
      <geometry>
        <box size="0.8 0.05 0.6"/>
      </geometry>
    </collision>
    <!-- Inertial properties - MOVED UP to match -->
    <inertial>
      <mass value="5.0"/>
      <origin rpy="0 0 0" xyz="0 0 0.3"/>
      <inertia ixx="0.6" ixy="0" ixz="0" iyy="0.88" iyz="0" izz="0.53"/>
    </inertial>
  </link>
  <!-- Wall Bracket Link (Fixed to wall) -->
  <link name="wall_bracket">
    <!-- Main wall bracket plate -->
    <visual>
      <origin rpy="0 0 0" xyz="0 0 0"/>
      <geometry>
        <box size="0.25 0.02 0.08"/>
      </geometry>
      <material name="wall_mount_steel"/>
    </visual>
    <!-- Reinforcement ribs -->
    <visual>
      <origin rpy="0 0 0" xyz="0.0625 0 0"/>
      <geometry>
        <box size="0.01 0.025 0.06"/>
      </geometry>
      <material name="wall_mount_steel"/>
    </visual>
    <visual>
      <origin rpy="0 0 0" xyz="-0.0625 0 0"/>
      <geometry>
        <box size="0.01 0.025 0.06"/>
      </geometry>
      <material name="wall_mount_steel"/>
    </visual>
    <!-- Wall mounting bolts (decorative) -->
    <visual>
      <origin rpy="1.570795 0 0" xyz="0.08333333333333333 -0.013000000000000001 0.02666666666666667"/>
      <geometry>
        <cylinder length="0.01" radius="0.004"/>
      </geometry>
      <material name="cable_black"/>
    </visual>
    <visual>
      <origin rpy="1.570795 0 0" xyz="-0.08333333333333333 -0.013000000000000001 0.02666666666666667"/>
      <geometry>
        <cylinder length="0.01" radius="0.004"/>
      </geometry>
      <material name="cable_black"/>
    </visual>
    <visual>
      <origin rpy="1.570795 0 0" xyz="0.08333333333333333 -0.013000000000000001 -0.02666666666666667"/>
      <geometry>
        <cylinder length="0.01" radius="0.004"/>
      </geometry>
      <material name="cable_black"/>
    </visual>
    <visual>
      <origin rpy="1.570795 0 0" xyz="-0.08333333333333333 -0.013000000000000001 -0.02666666666666667"/>
      <geometry>
        <cylinder length="0.01" radius="0.004"/>
      </geometry>
      <material name="cable_black"/>
    </visual>
    <collision>
      <origin rpy="0 0 0" xyz="0 0 0"/>
      <geometry>
        <box size="0.25 0.02 0.08"/>
      </geometry>
    </collision>
    <inertial>
      <mass value="2.8"/>
      <origin rpy="0 0 0" xyz="0 0 0"/>
      <inertia ixx="0.025" ixy="0" ixz="0" iyy="0.035" iyz="0" izz="0.045"/>
    </inertial>
  </link>
  <!-- Wall Mount Housing Link (Extends from wall) -->
  <link name="wall_mount">
    <!-- Main mounting arm -->
    <visual>
      <origin rpy="1.570795 0 0" xyz="0 0.06 0"/>
      <geometry>
        <cylinder length="0.12" radius="0.025"/>
      </geometry>
      <material name="wall_mount_steel"/>
    </visual>
    <!-- Mounting platform -->
    <visual>
      <origin rpy="0 0 0" xyz="0 0.12 0"/>
      <geometry>
        <box size="0.2 0.15 0.02"/>
      </geometry>
      <material name="wall_mount_steel"/>
    </visual>
    <!-- Platform reinforcement -->
    <visual>
      <origin rpy="0 0 0" xyz="0 0.195 0"/>
      <geometry>
        <box size="0.18000000000000002 0.01 0.025"/>
      </geometry>
      <material name="wall_mount_steel"/>
    </visual>
    <!-- Cable management channel -->
    <visual>
      <origin rpy="1.570795 0 0" xyz="0.06666666666666667 0.06 0"/>
      <geometry>
        <cylinder length="0.12" radius="0.008"/>
      </geometry>
      <material name="cable_black"/>
    </visual>
    <!-- Safety markings -->
    <visual>
      <origin rpy="0 0 0" xyz="0 0.265 0.011"/>
      <geometry>
        <box size="0.19 0.01 0.002"/>
      </geometry>
      <material name="safety_orange"/>
    </visual>
    <collision>
      <origin rpy="0 0 0" xyz="0 0.06 0"/>
      <geometry>
        <box size="0.2 0.12 0.15"/>
      </geometry>
    </collision>
    <inertial>
      <mass value="4.2"/>
      <origin rpy="0 0 0" xyz="0 0.06 0"/>
      <inertia ixx="0.045" ixy="0" ixz="0" iyy="0.035" iyz="0" izz="0.065"/>
    </inertial>
  </link>
  <!-- World to Wall Bracket Joint (fixed to wall plate) -->
  <joint name="world_to_wall_bracket" type="fixed">
    <parent link="world"/>
    <child link="wall_bracket"/>
    <origin rpy="0 0 0" xyz="0 0.025 0.3"/>
  </joint>
  <!-- Wall Bracket to Mount Joint (fixed extension from wall) -->
  <joint name="wall_bracket_to_mount" type="fixed">
    <parent link="wall_bracket"/>
    <child link="wall_mount"/>
    <origin rpy="0 0 0" xyz="0 0.01 0"/>
  </joint>
  <!-- Base Link Assembly (Professional base with motor housing) -->
  <link name="base_link">
    <!-- Main base platform -->
    <visual>
      <origin rpy="0 0 0" xyz="0 0 0.04"/>
      <geometry>
        <cylinder length="0.08" radius="0.06"/>
      </geometry>
      <material name="medical_base"/>
    </visual>
    <!-- Motor housing on top -->
    <visual>
      <origin rpy="0 0 0" xyz="0 0 0.0975"/>
      <geometry>
        <cylinder length="0.035" radius="0.04"/>
      </geometry>
      <material name="motor_black"/>
    </visual>
    <!-- Mounting bolts (decorative) -->
    <visual>
      <origin rpy="0 0 0" xyz="0.04 0 0.02"/>
      <geometry>
        <cylinder length="0.01" radius="0.003"/>
      </geometry>
      <material name="cable_black"/>
    </visual>
    <visual>
      <origin rpy="0 0 0" xyz="-0.04 0 0.02"/>
      <geometry>
        <cylinder length="0.01" radius="0.003"/>
      </geometry>
      <material name="cable_black"/>
    </visual>
    <visual>
      <origin rpy="0 0 0" xyz="0 0.04 0.02"/>
      <geometry>
        <cylinder length="0.01" radius="0.003"/>
      </geometry>
      <material name="cable_black"/>
    </visual>
    <visual>
      <origin rpy="0 0 0" xyz="0 -0.04 0.02"/>
      <geometry>
        <cylinder length="0.01" radius="0.003"/>
      </geometry>
      <material name="cable_black"/>
    </visual>
    <collision>
      <origin rpy="0 0 0" xyz="0 0 0.04"/>
      <geometry>
        <cylinder length="0.08" radius="0.06"/>
      </geometry>
    </collision>
    <inertial>
      <mass value="3.5"/>
      <origin rpy="0 0 0" xyz="0 0 0.04"/>
      <inertia ixx="0.035" ixy="0" ixz="0" iyy="0.035" iyz="0" izz="0.055"/>
    </inertial>
  </link>
  <!-- Wall Mount to Base Joint (robot mounts on wall platform) -->
  <joint name="wall_mount_to_base" type="fixed">
    <parent link="wall_mount"/>
    <child link="base_link"/>
    <origin rpy="0 0 0" xyz="0 0.27 0"/>
  </joint>
  <!-- Shoulder Link Assembly -->
  <link name="shoulder_link">
    <!-- Main shoulder structure -->
    <visual>
      <origin rpy="0 0 0" xyz="0 0 0.05"/>
      <geometry>
        <cylinder length="0.1" radius="0.035"/>
      </geometry>
      <material name="medical_grey"/>
    </visual>
    <!-- Motor housing at top -->
    <visual>
      <origin rpy="0 0 0" xyz="0 0 0.12000000000000001"/>
      <geometry>
        <cylinder length="0.04" radius="0.03"/>
      </geometry>
      <material name="motor_black"/>
    </visual>
    <!-- Cable management -->
    <visual>
      <origin rpy="0 0 0" xyz="0.0175 0 0.05"/>
      <geometry>
        <box size="0.008 0.008 0.1"/>
      </geometry>
      <material name="cable_black"/>
    </visual>
    <!-- Safety stripe -->
    <visual>
      <origin rpy="0 0 0" xyz="0 0 0.09000000000000001"/>
      <geometry>
        <cylinder length="0.005" radius="0.036000000000000004"/>
      </geometry>
      <material name="safety_orange"/>
    </visual>
    <collision>
      <origin rpy="0 0 0" xyz="0 0 0.05"/>
      <geometry>
        <cylinder length="0.1" radius="0.035"/>
      </geometry>
    </collision>
    <inertial>
      <mass value="1.8"/>
      <origin rpy="0 0 0" xyz="0 0 0.05"/>
      <inertia ixx="0.015" ixy="0" ixz="0" iyy="0.015" iyz="0" izz="0.008"/>
    </inertial>
  </link>
  <!-- Joint 1: Shoulder Roll (IDENTICAL movement) -->
  <joint name="shoulder_roll" type="revolute">
    <parent link="base_link"/>
    <child link="shoulder_link"/>
    <origin rpy="0 0 0" xyz="0 0 0.115"/>
    <axis xyz="0 0 1"/>
    <limit effort="10.0" lower="-1.570795" upper="1.570795" velocity="1.0"/>
  </joint>
  <!-- Upper Arm Link Assembly (Humerus) -->
  <link name="upper_arm_link">
    <!-- Main upper arm structure -->
    <visual>
      <origin rpy="1.570795 0 0" xyz="0 0.11 0"/>
      <geometry>
        <cylinder length="0.22" radius="0.028"/>
      </geometry>
      <material name="medical_grey"/>
    </visual>
    <!-- Motor housing at shoulder end -->
    <visual>
      <origin rpy="0 0 0" xyz="0 0 0"/>
      <geometry>
        <cylinder length="0.035" radius="0.025"/>
      </geometry>
      <material name="motor_black"/>
    </visual>
    <!-- Reinforcement plates -->
    <visual>
      <origin rpy="0 0 0" xyz="0 0.055 0"/>
      <geometry>
        <box size="0.05 0.02 0.03"/>
      </geometry>
      <material name="medical_grey"/>
    </visual>
    <visual>
      <origin rpy="0 0 0" xyz="0 0.165 0"/>
      <geometry>
        <box size="0.05 0.02 0.03"/>
      </geometry>
      <material name="medical_grey"/>
    </visual>
    <!-- Cable routing -->
    <visual>
      <origin rpy="1.570795 0 0" xyz="0.014 0.11 0"/>
      <geometry>
        <cylinder length="0.22" radius="0.004"/>
      </geometry>
      <material name="cable_black"/>
    </visual>
    <collision>
      <origin rpy="1.570795 0 0" xyz="0 0.11 0"/>
      <geometry>
        <cylinder length="0.22" radius="0.028"/>
      </geometry>
    </collision>
    <inertial>
      <mass value="2.2"/>
      <origin rpy="0 0 0" xyz="0 0.11 0"/>
      <inertia ixx="0.08" ixy="0" ixz="0" iyy="0.008" iyz="0" izz="0.08"/>
    </inertial>
  </link>
  <!-- Joint 2: Shoulder Pitch (IDENTICAL movement) -->
  <joint name="shoulder_pitch" type="revolute">
    <parent link="shoulder_link"/>
    <child link="upper_arm_link"/>
    <origin rpy="0 0 0" xyz="0 0 0.14"/>
    <axis xyz="1 0 0"/>
    <limit effort="8.0" lower="-0.5235983333333333" upper="2.6179916666666667" velocity="1.0"/>
  </joint>
  <!-- Forearm Link Assembly (Radius/Ulna) -->
  <link name="forearm_link">
    <!-- Main forearm structure -->
    <visual>
      <origin rpy="1.570795 0 0" xyz="0 0.1 0"/>
      <geometry>
        <cylinder length="0.2" radius="0.022"/>
      </geometry>
      <material name="medical_grey"/>
    </visual>
    <!-- Motor housing at elbow -->
    <visual>
      <origin rpy="0 0 0" xyz="0 0 0"/>
      <geometry>
        <cylinder length="0.03" radius="0.02"/>
      </geometry>
      <material name="motor_black"/>
    </visual>
    <!-- Structural reinforcement -->
    <visual>
      <origin rpy="0 0 0" xyz="0 0.06666666666666667 0"/>
      <geometry>
        <box size="0.04 0.015 0.025"/>
      </geometry>
      <material name="medical_grey"/>
    </visual>
    <visual>
      <origin rpy="0 0 0" xyz="0 0.13333333333333333 0"/>
      <geometry>
        <box size="0.04 0.015 0.025"/>
      </geometry>
      <material name="medical_grey"/>
    </visual>
    <!-- Cable management -->
    <visual>
      <origin rpy="1.570795 0 0" xyz="0.011 0.1 0"/>
      <geometry>
        <cylinder length="0.2" radius="0.003"/>
      </geometry>
      <material name="cable_black"/>
    </visual>
    <collision>
      <origin rpy="1.570795 0 0" xyz="0 0.1 0"/>
      <geometry>
        <cylinder length="0.2" radius="0.022"/>
      </geometry>
    </collision>
    <inertial>
      <mass value="1.5"/>
      <origin rpy="0 0 0" xyz="0 0.1 0"/>
      <inertia ixx="0.05" ixy="0" ixz="0" iyy="0.005" iyz="0" izz="0.05"/>
    </inertial>
  </link>
  <!-- Joint 3: Shoulder Yaw (IDENTICAL movement) -->
  <joint name="shoulder_yaw" type="revolute">
    <parent link="upper_arm_link"/>
    <child link="forearm_link"/>
    <origin rpy="0 0 0" xyz="0 0.22 0"/>
    <axis xyz="0 0 1"/>
    <limit effort="6.0" lower="-0.3490655555555555" upper="1.570795" velocity="1.0"/>
  </joint>
  <!-- Wrist Link Assembly -->
  <link name="wrist_link">
    <!-- Main wrist structure -->
    <visual>
      <origin rpy="1.570795 0 0" xyz="0 0.04 0"/>
      <geometry>
        <cylinder length="0.08" radius="0.02"/>
      </geometry>
      <material name="medical_grey"/>
    </visual>
    <!-- Motor housing -->
    <visual>
      <origin rpy="0 0 0" xyz="0 0 0"/>
      <geometry>
        <cylinder length="0.025" radius="0.018"/>
      </geometry>
      <material name="motor_black"/>
    </visual>
    <!-- Joint cover -->
    <visual>
      <origin rpy="0 0 0" xyz="0 0.08 0"/>
      <geometry>
        <cylinder length="0.01" radius="0.022"/>
      </geometry>
      <material name="safety_orange"/>
    </visual>
    <collision>
      <origin rpy="1.570795 0 0" xyz="0 0.04 0"/>
      <geometry>
        <cylinder length="0.08" radius="0.02"/>
      </geometry>
    </collision>
    <inertial>
      <mass value="0.8"/>
      <origin rpy="0 0 0" xyz="0 0.04 0"/>
      <inertia ixx="0.004" ixy="0" ixz="0" iyy="0.002" iyz="0" izz="0.004"/>
    </inertial>
  </link>
  <!-- Joint 4: Elbow Flexion (IDENTICAL movement) -->
  <joint name="elbow_flexion" type="revolute">
    <parent link="forearm_link"/>
    <child link="wrist_link"/>
    <origin rpy="0 0 0" xyz="0 0.2 0"/>
    <axis xyz="1 0 0"/>
    <limit effort="4.0" lower="-0.5235983333333333" upper="2.6179916666666667" velocity="1.0"/>
  </joint>
  <!-- Hand Link Assembly -->
  <link name="hand_link">
    <!-- Main hand structure -->
    <visual>
      <origin rpy="1.570795 0 0" xyz="0 0.03 0"/>
      <geometry>
        <cylinder length="0.06" radius="0.018"/>
      </geometry>
      <material name="surgical_steel"/>
    </visual>
    <!-- Motor housing -->
    <visual>
      <origin rpy="0 0 0" xyz="0 0 0"/>
      <geometry>
        <cylinder length="0.02" radius="0.015"/>
      </geometry>
      <material name="motor_black"/>
    </visual>
    <!-- Tool interface -->
    <visual>
      <origin rpy="0 0 0" xyz="0 0.06 0"/>
      <geometry>
        <cylinder length="0.005" radius="0.016"/>
      </geometry>
      <material name="safety_orange"/>
    </visual>
    <collision>
      <origin rpy="1.570795 0 0" xyz="0 0.03 0"/>
      <geometry>
        <cylinder length="0.06" radius="0.018"/>
      </geometry>
    </collision>
    <inertial>
      <mass value="0.4"/>
      <origin rpy="0 0 0" xyz="0 0.03 0"/>
      <inertia ixx="0.001" ixy="0" ixz="0" iyy="0.0008" iyz="0" izz="0.001"/>
    </inertial>
  </link>
  <!-- Joint 5: Wrist Roll (IDENTICAL movement) -->
  <joint name="wrist_roll" type="revolute">
    <parent link="wrist_link"/>
    <child link="hand_link"/>
    <origin rpy="0 0 0" xyz="0 0.08 0"/>
    <axis xyz="0 1 0"/>
    <limit effort="2.0" lower="-1.570795" upper="1.570795" velocity="2.0"/>
  </joint>
  <!-- Tool Housing Link (Contains the needle extension mechanism) -->
  <link name="tool_housing_link">
    <!-- Main tool housing -->
    <visual>
      <origin rpy="1.570795 0 0" xyz="0 0.04 0"/>
      <geometry>
        <cylinder length="0.08" radius="0.008"/>
      </geometry>
      <material name="surgical_steel"/>
    </visual>
    <!-- Housing interface -->
    <visual>
      <origin rpy="1.570795 0 0" xyz="0 0.01 0"/>
      <geometry>
        <cylinder length="0.02" radius="0.006"/>
      </geometry>
      <material name="motor_black"/>
    </visual>
    <!-- Extension mechanism housing -->
    <visual>
      <origin rpy="0 0 0" xyz="0 0.065 0"/>
      <geometry>
        <cylinder length="0.02" radius="0.01"/>
      </geometry>
      <material name="safety_orange"/>
    </visual>
    <!-- Needle guide -->
    <visual>
      <origin rpy="1.570795 0 0" xyz="0 0.08 0"/>
      <geometry>
        <cylinder length="0.005" radius="0.001"/>
      </geometry>
      <material name="needle_gold"/>
    </visual>
    <collision>
      <origin rpy="1.570795 0 0" xyz="0 0.04 0"/>
      <geometry>
        <cylinder length="0.08" radius="0.008"/>
      </geometry>
    </collision>
    <inertial>
      <mass value="0.12"/>
      <origin rpy="0 0 0" xyz="0 0.04 0"/>
      <inertia ixx="0.0002" ixy="0" ixz="0" iyy="0.0002" iyz="0" izz="0.00002"/>
    </inertial>
  </link>
  <!-- Joint 6: Wrist Pitch (IDENTICAL movement) -->
  <joint name="wrist_pitch" type="revolute">
    <parent link="hand_link"/>
    <child link="tool_housing_link"/>
    <origin rpy="0 0 0" xyz="0 0.06 0"/>
    <axis xyz="1 0 0"/>
    <limit effort="1.0" lower="-0.7853975" upper="0.7853975" velocity="2.0"/>
  </joint>
  <!-- Needle Link (Dynamic length needle - grows in both directions) -->
  <link name="needle_link">
    <!-- Extended needle rear section (extends much further backward into housing) -->
    <visual>
      <origin rpy="1.570795 0 0" xyz="0 -0.06 0"/>
      <geometry>
        <cylinder length="0.12" radius="0.0008"/>
      </geometry>
      <material name="surgical_steel"/>
    </visual>
    <!-- Main needle body (extends forward) -->
    <visual>
      <origin rpy="1.570795 0 0" xyz="0 0.06 0"/>
      <geometry>
        <cylinder length="0.12" radius="0.0005"/>
      </geometry>
      <material name="needle_gold"/>
    </visual>
    <!-- Needle tip -->
    <visual>
      <origin rpy="0 0 0" xyz="0 0.12 0"/>
      <geometry>
        <sphere radius="0.00075"/>
      </geometry>
      <material name="needle_gold"/>
    </visual>
    <!-- Connection piece (always at housing exit) -->
    <visual>
      <origin rpy="1.570795 0 0" xyz="0 0.001 0"/>
      <geometry>
        <cylinder length="0.002" radius="0.001"/>
      </geometry>
      <material name="safety_orange"/>
    </visual>
    <collision>
      <origin rpy="1.570795 0 0" xyz="0 0.03 0"/>
      <geometry>
        <cylinder length="0.18" radius="0.001"/>
      </geometry>
    </collision>
    <inertial>
      <mass value="0.006"/>
      <origin rpy="0 0 0" xyz="0 0.03 0"/>
      <inertia ixx="0.000006" ixy="0" ixz="0" iyy="0.000001" iyz="0" izz="0.000006"/>
    </inertial>
  </link>
  <!-- Joint 7: Needle Extension (NEW 7th DOF - Prismatic) -->
  <!-- The needle grows in both directions: -->
  <!-- - Forward: for surgical reach -->
  <!-- - Backward: to maintain connection with housing mechanism -->
  <joint name="needle_extension" type="prismatic">
    <parent link="tool_housing_link"/>
    <child link="needle_link"/>
    <origin rpy="0 0 0" xyz="0 0.08 0"/>
    <axis xyz="0 1 0"/>
    <limit effort="5.0" lower="0.0" upper="0.12" velocity="0.05"/>
  </joint>
  <!-- Needle Tip Frame (for precise neurosurgical targeting) -->
  <link name="needle_tip"/>
  <joint name="needle_tip_joint" type="fixed">
    <parent link="needle_link"/>
    <child link="needle_tip"/>
    <origin rpy="0 0 0" xyz="0 0.12 0"/>
  </joint>
</robot>
